INFO:     Will watch for changes in these directories: ['/Users/juanpelos/Documents/Data_Bases/Data_Bases_2.0/project_2/app']
INFO:     Uvicorn running on http://0.0.0.0:8000 (Press CTRL+C to quit)
INFO:     Started reloader process [69960] using WatchFiles

  You can now view your Streamlit app in your browser.

  Local URL: http://localhost:8501
  Network URL: http://192.168.2.12:8501

INFO:     Started server process [69968]
INFO:     Waiting for application startup.
INFO:     Application startup complete.
/Users/juanpelos/Documents/.venv/lib/python3.9/site-packages/urllib3/__init__.py:35: NotOpenSSLWarning: urllib3 v2 only supports OpenSSL 1.1.1+, currently the 'ssl' module is compiled with 'LibreSSL 2.8.3'. See: https://github.com/urllib3/urllib3/issues/3020
  warnings.warn(
INFO:     127.0.0.1:49504 - "GET /sellers/ HTTP/1.1" 200 OK
INFO:     Will watch for changes in these directories: ['/Users/juanpelos/Documents/Data_Bases/Data_Bases_2.0/project_2/app']
ERROR:    [Errno 48] Address already in use

  You can now view your Streamlit app in your browser.

  Local URL: http://localhost:8502
  Network URL: http://192.168.2.12:8502

/Users/juanpelos/Documents/.venv/lib/python3.9/site-packages/urllib3/__init__.py:35: NotOpenSSLWarning: urllib3 v2 only supports OpenSSL 1.1.1+, currently the 'ssl' module is compiled with 'LibreSSL 2.8.3'. See: https://github.com/urllib3/urllib3/issues/3020
  warnings.warn(
INFO:     127.0.0.1:49559 - "GET /sellers/ HTTP/1.1" 200 OK
INFO:     127.0.0.1:49561 - "GET /sellers/ HTTP/1.1" 200 OK
INFO:     Will watch for changes in these directories: ['/Users/juanpelos/Documents/Data_Bases/Data_Bases_2.0/project_2/app']
ERROR:    [Errno 48] Address already in use

  You can now view your Streamlit app in your browser.

  Local URL: http://localhost:8503
  Network URL: http://192.168.2.12:8503

/Users/juanpelos/Documents/.venv/lib/python3.9/site-packages/urllib3/__init__.py:35: NotOpenSSLWarning: urllib3 v2 only supports OpenSSL 1.1.1+, currently the 'ssl' module is compiled with 'LibreSSL 2.8.3'. See: https://github.com/urllib3/urllib3/issues/3020
  warnings.warn(
WARNING:  WatchFiles detected changes in 'main.py'. Reloading...
INFO:     Shutting down
INFO:     Waiting for application shutdown.
INFO:     Application shutdown complete.
INFO:     Finished server process [69968]
Process SpawnProcess-2:
Traceback (most recent call last):
  File "/Applications/Xcode.app/Contents/Developer/Library/Frameworks/Python3.framework/Versions/3.9/lib/python3.9/multiprocessing/process.py", line 315, in _bootstrap
    self.run()
  File "/Applications/Xcode.app/Contents/Developer/Library/Frameworks/Python3.framework/Versions/3.9/lib/python3.9/multiprocessing/process.py", line 108, in run
    self._target(*self._args, **self._kwargs)
  File "/Users/juanpelos/Documents/.venv/lib/python3.9/site-packages/uvicorn/_subprocess.py", line 73, in subprocess_started
    sys.stdin = os.fdopen(stdin_fileno)  # pragma: full coverage
  File "/Applications/Xcode.app/Contents/Developer/Library/Frameworks/Python3.framework/Versions/3.9/lib/python3.9/os.py", line 1023, in fdopen
    return io.open(fd, *args, **kwargs)
OSError: [Errno 9] Bad file descriptor
WARNING:  WatchFiles detected changes in 'streamlit_app.py'. Reloading...
Process SpawnProcess-3:
Traceback (most recent call last):
  File "/Applications/Xcode.app/Contents/Developer/Library/Frameworks/Python3.framework/Versions/3.9/lib/python3.9/multiprocessing/process.py", line 315, in _bootstrap
    self.run()
  File "/Applications/Xcode.app/Contents/Developer/Library/Frameworks/Python3.framework/Versions/3.9/lib/python3.9/multiprocessing/process.py", line 108, in run
    self._target(*self._args, **self._kwargs)
  File "/Users/juanpelos/Documents/.venv/lib/python3.9/site-packages/uvicorn/_subprocess.py", line 73, in subprocess_started
    sys.stdin = os.fdopen(stdin_fileno)  # pragma: full coverage
  File "/Applications/Xcode.app/Contents/Developer/Library/Frameworks/Python3.framework/Versions/3.9/lib/python3.9/os.py", line 1023, in fdopen
    return io.open(fd, *args, **kwargs)
OSError: [Errno 9] Bad file descriptor
INFO:     Will watch for changes in these directories: ['/Users/juanpelos/Documents/Data_Bases/Data_Bases_2.0/project_2/app']
ERROR:    [Errno 48] Address already in use

  You can now view your Streamlit app in your browser.

  Local URL: http://localhost:8504
  Network URL: http://192.168.2.12:8504

/Users/juanpelos/Documents/.venv/lib/python3.9/site-packages/urllib3/__init__.py:35: NotOpenSSLWarning: urllib3 v2 only supports OpenSSL 1.1.1+, currently the 'ssl' module is compiled with 'LibreSSL 2.8.3'. See: https://github.com/urllib3/urllib3/issues/3020
  warnings.warn(
WARNING:  WatchFiles detected changes in 'main.py'. Reloading...
Process SpawnProcess-4:
Traceback (most recent call last):
  File "/Applications/Xcode.app/Contents/Developer/Library/Frameworks/Python3.framework/Versions/3.9/lib/python3.9/multiprocessing/process.py", line 315, in _bootstrap
    self.run()
  File "/Applications/Xcode.app/Contents/Developer/Library/Frameworks/Python3.framework/Versions/3.9/lib/python3.9/multiprocessing/process.py", line 108, in run
    self._target(*self._args, **self._kwargs)
  File "/Users/juanpelos/Documents/.venv/lib/python3.9/site-packages/uvicorn/_subprocess.py", line 73, in subprocess_started
    sys.stdin = os.fdopen(stdin_fileno)  # pragma: full coverage
  File "/Applications/Xcode.app/Contents/Developer/Library/Frameworks/Python3.framework/Versions/3.9/lib/python3.9/os.py", line 1023, in fdopen
    return io.open(fd, *args, **kwargs)
OSError: [Errno 9] Bad file descriptor
WARNING:  WatchFiles detected changes in 'streamlit_app.py'. Reloading...
Process SpawnProcess-5:
Traceback (most recent call last):
  File "/Applications/Xcode.app/Contents/Developer/Library/Frameworks/Python3.framework/Versions/3.9/lib/python3.9/multiprocessing/process.py", line 315, in _bootstrap
    self.run()
  File "/Applications/Xcode.app/Contents/Developer/Library/Frameworks/Python3.framework/Versions/3.9/lib/python3.9/multiprocessing/process.py", line 108, in run
    self._target(*self._args, **self._kwargs)
  File "/Users/juanpelos/Documents/.venv/lib/python3.9/site-packages/uvicorn/_subprocess.py", line 73, in subprocess_started
    sys.stdin = os.fdopen(stdin_fileno)  # pragma: full coverage
  File "/Applications/Xcode.app/Contents/Developer/Library/Frameworks/Python3.framework/Versions/3.9/lib/python3.9/os.py", line 1023, in fdopen
    return io.open(fd, *args, **kwargs)
OSError: [Errno 9] Bad file descriptor
WARNING:  WatchFiles detected changes in 'main.py'. Reloading...
Process SpawnProcess-6:
Traceback (most recent call last):
  File "/Applications/Xcode.app/Contents/Developer/Library/Frameworks/Python3.framework/Versions/3.9/lib/python3.9/multiprocessing/process.py", line 315, in _bootstrap
    self.run()
  File "/Applications/Xcode.app/Contents/Developer/Library/Frameworks/Python3.framework/Versions/3.9/lib/python3.9/multiprocessing/process.py", line 108, in run
    self._target(*self._args, **self._kwargs)
  File "/Users/juanpelos/Documents/.venv/lib/python3.9/site-packages/uvicorn/_subprocess.py", line 73, in subprocess_started
    sys.stdin = os.fdopen(stdin_fileno)  # pragma: full coverage
  File "/Applications/Xcode.app/Contents/Developer/Library/Frameworks/Python3.framework/Versions/3.9/lib/python3.9/os.py", line 1023, in fdopen
    return io.open(fd, *args, **kwargs)
OSError: [Errno 9] Bad file descriptor
WARNING:  WatchFiles detected changes in 'streamlit_app.py'. Reloading...
Process SpawnProcess-7:
Traceback (most recent call last):
  File "/Applications/Xcode.app/Contents/Developer/Library/Frameworks/Python3.framework/Versions/3.9/lib/python3.9/multiprocessing/process.py", line 315, in _bootstrap
    self.run()
  File "/Applications/Xcode.app/Contents/Developer/Library/Frameworks/Python3.framework/Versions/3.9/lib/python3.9/multiprocessing/process.py", line 108, in run
    self._target(*self._args, **self._kwargs)
  File "/Users/juanpelos/Documents/.venv/lib/python3.9/site-packages/uvicorn/_subprocess.py", line 73, in subprocess_started
    sys.stdin = os.fdopen(stdin_fileno)  # pragma: full coverage
  File "/Applications/Xcode.app/Contents/Developer/Library/Frameworks/Python3.framework/Versions/3.9/lib/python3.9/os.py", line 1023, in fdopen
    return io.open(fd, *args, **kwargs)
OSError: [Errno 9] Bad file descriptor
INFO:     Will watch for changes in these directories: ['/Users/juanpelos/Documents/Data_Bases/Data_Bases_2.0/project_2/app']
ERROR:    [Errno 48] Address already in use

  You can now view your Streamlit app in your browser.

  Local URL: http://localhost:8505
  Network URL: http://192.168.2.12:8505

/Users/juanpelos/Documents/.venv/lib/python3.9/site-packages/urllib3/__init__.py:35: NotOpenSSLWarning: urllib3 v2 only supports OpenSSL 1.1.1+, currently the 'ssl' module is compiled with 'LibreSSL 2.8.3'. See: https://github.com/urllib3/urllib3/issues/3020
  warnings.warn(
2024-11-03 20:42:48.513 Uncaught app exception
Traceback (most recent call last):
  File "/Users/juanpelos/Documents/.venv/lib/python3.9/site-packages/streamlit/runtime/scriptrunner/exec_code.py", line 88, in exec_func_with_error_handling
    result = func()
  File "/Users/juanpelos/Documents/.venv/lib/python3.9/site-packages/streamlit/runtime/scriptrunner/script_runner.py", line 590, in code_to_exec
    exec(code, module.__dict__)
  File "/Users/juanpelos/Documents/Data_Bases/Data_Bases_2.0/project_2/app/streamlit_app.py", line 45, in <module>
    crear_seller() if tabla_seleccionada == "Sellers" else st.warning("Funci√≥n no implementada")
  File "/Users/juanpelos/Documents/.venv/lib/python3.9/site-packages/streamlit/runtime/metrics_util.py", line 410, in wrapped_func
    result = non_optional_func(*args, **kwargs)
  File "/Users/juanpelos/Documents/.venv/lib/python3.9/site-packages/streamlit/runtime/scriptrunner/magic_funcs.py", line 29, in transparent_write
    st.write(*args)
  File "/Users/juanpelos/Documents/.venv/lib/python3.9/site-packages/streamlit/runtime/metrics_util.py", line 410, in wrapped_func
    result = non_optional_func(*args, **kwargs)
  File "/Users/juanpelos/Documents/.venv/lib/python3.9/site-packages/streamlit/elements/write.py", line 423, in write
    self.dg.dataframe(arg)
  File "/Users/juanpelos/Documents/.venv/lib/python3.9/site-packages/streamlit/runtime/metrics_util.py", line 410, in wrapped_func
    result = non_optional_func(*args, **kwargs)
  File "/Users/juanpelos/Documents/.venv/lib/python3.9/site-packages/streamlit/elements/arrow.py", line 549, in dataframe
    data_df = dataframe_util.convert_anything_to_pandas_df(
  File "/Users/juanpelos/Documents/.venv/lib/python3.9/site-packages/streamlit/dataframe_util.py", line 679, in convert_anything_to_pandas_df
    [d[0] if d else "" for d in data.description] if data.description else None
TypeError: 'function' object is not iterable
2024-11-03 20:42:56.947 Uncaught app exception
Traceback (most recent call last):
  File "/Users/juanpelos/Documents/.venv/lib/python3.9/site-packages/streamlit/runtime/scriptrunner/exec_code.py", line 88, in exec_func_with_error_handling
    result = func()
  File "/Users/juanpelos/Documents/.venv/lib/python3.9/site-packages/streamlit/runtime/scriptrunner/script_runner.py", line 590, in code_to_exec
    exec(code, module.__dict__)
  File "/Users/juanpelos/Documents/Data_Bases/Data_Bases_2.0/project_2/app/streamlit_app.py", line 45, in <module>
    crear_seller() if tabla_seleccionada == "Sellers" else st.warning("Funci√≥n no implementada")
  File "/Users/juanpelos/Documents/.venv/lib/python3.9/site-packages/streamlit/runtime/metrics_util.py", line 410, in wrapped_func
    result = non_optional_func(*args, **kwargs)
  File "/Users/juanpelos/Documents/.venv/lib/python3.9/site-packages/streamlit/runtime/scriptrunner/magic_funcs.py", line 29, in transparent_write
    st.write(*args)
  File "/Users/juanpelos/Documents/.venv/lib/python3.9/site-packages/streamlit/runtime/metrics_util.py", line 410, in wrapped_func
    result = non_optional_func(*args, **kwargs)
  File "/Users/juanpelos/Documents/.venv/lib/python3.9/site-packages/streamlit/elements/write.py", line 423, in write
    self.dg.dataframe(arg)
  File "/Users/juanpelos/Documents/.venv/lib/python3.9/site-packages/streamlit/runtime/metrics_util.py", line 410, in wrapped_func
    result = non_optional_func(*args, **kwargs)
  File "/Users/juanpelos/Documents/.venv/lib/python3.9/site-packages/streamlit/elements/arrow.py", line 549, in dataframe
    data_df = dataframe_util.convert_anything_to_pandas_df(
  File "/Users/juanpelos/Documents/.venv/lib/python3.9/site-packages/streamlit/dataframe_util.py", line 679, in convert_anything_to_pandas_df
    [d[0] if d else "" for d in data.description] if data.description else None
TypeError: 'function' object is not iterable
WARNING:  WatchFiles detected changes in 'streamlit_app.py'. Reloading...
Process SpawnProcess-8:
Traceback (most recent call last):
  File "/Applications/Xcode.app/Contents/Developer/Library/Frameworks/Python3.framework/Versions/3.9/lib/python3.9/multiprocessing/process.py", line 315, in _bootstrap
    self.run()
  File "/Applications/Xcode.app/Contents/Developer/Library/Frameworks/Python3.framework/Versions/3.9/lib/python3.9/multiprocessing/process.py", line 108, in run
    self._target(*self._args, **self._kwargs)
  File "/Users/juanpelos/Documents/.venv/lib/python3.9/site-packages/uvicorn/_subprocess.py", line 73, in subprocess_started
    sys.stdin = os.fdopen(stdin_fileno)  # pragma: full coverage
  File "/Applications/Xcode.app/Contents/Developer/Library/Frameworks/Python3.framework/Versions/3.9/lib/python3.9/os.py", line 1023, in fdopen
    return io.open(fd, *args, **kwargs)
OSError: [Errno 9] Bad file descriptor
INFO:     Will watch for changes in these directories: ['/Users/juanpelos/Documents/Data_Bases/Data_Bases_2.0/project_2/app']
ERROR:    [Errno 48] Address already in use

  You can now view your Streamlit app in your browser.

  Local URL: http://localhost:8506
  Network URL: http://192.168.2.12:8506

/Users/juanpelos/Documents/.venv/lib/python3.9/site-packages/urllib3/__init__.py:35: NotOpenSSLWarning: urllib3 v2 only supports OpenSSL 1.1.1+, currently the 'ssl' module is compiled with 'LibreSSL 2.8.3'. See: https://github.com/urllib3/urllib3/issues/3020
  warnings.warn(
WARNING:  WatchFiles detected changes in 'streamlit_app.py'. Reloading...
Process SpawnProcess-9:
Traceback (most recent call last):
  File "/Applications/Xcode.app/Contents/Developer/Library/Frameworks/Python3.framework/Versions/3.9/lib/python3.9/multiprocessing/process.py", line 315, in _bootstrap
    self.run()
  File "/Applications/Xcode.app/Contents/Developer/Library/Frameworks/Python3.framework/Versions/3.9/lib/python3.9/multiprocessing/process.py", line 108, in run
    self._target(*self._args, **self._kwargs)
  File "/Users/juanpelos/Documents/.venv/lib/python3.9/site-packages/uvicorn/_subprocess.py", line 73, in subprocess_started
    sys.stdin = os.fdopen(stdin_fileno)  # pragma: full coverage
  File "/Applications/Xcode.app/Contents/Developer/Library/Frameworks/Python3.framework/Versions/3.9/lib/python3.9/os.py", line 1023, in fdopen
    return io.open(fd, *args, **kwargs)
OSError: [Errno 9] Bad file descriptor
INFO:     Will watch for changes in these directories: ['/Users/juanpelos/Documents/Data_Bases/Data_Bases_2.0/project_2/app']
ERROR:    [Errno 48] Address already in use

  You can now view your Streamlit app in your browser.

  Local URL: http://localhost:8507
  Network URL: http://192.168.2.12:8507

/Users/juanpelos/Documents/.venv/lib/python3.9/site-packages/urllib3/__init__.py:35: NotOpenSSLWarning: urllib3 v2 only supports OpenSSL 1.1.1+, currently the 'ssl' module is compiled with 'LibreSSL 2.8.3'. See: https://github.com/urllib3/urllib3/issues/3020
  warnings.warn(
WARNING:  WatchFiles detected changes in 'main.py'. Reloading...
Process SpawnProcess-10:
Traceback (most recent call last):
  File "/Applications/Xcode.app/Contents/Developer/Library/Frameworks/Python3.framework/Versions/3.9/lib/python3.9/multiprocessing/process.py", line 315, in _bootstrap
    self.run()
  File "/Applications/Xcode.app/Contents/Developer/Library/Frameworks/Python3.framework/Versions/3.9/lib/python3.9/multiprocessing/process.py", line 108, in run
    self._target(*self._args, **self._kwargs)
  File "/Users/juanpelos/Documents/.venv/lib/python3.9/site-packages/uvicorn/_subprocess.py", line 73, in subprocess_started
    sys.stdin = os.fdopen(stdin_fileno)  # pragma: full coverage
  File "/Applications/Xcode.app/Contents/Developer/Library/Frameworks/Python3.framework/Versions/3.9/lib/python3.9/os.py", line 1023, in fdopen
    return io.open(fd, *args, **kwargs)
OSError: [Errno 9] Bad file descriptor
WARNING:  WatchFiles detected changes in 'streamlit_app.py'. Reloading...
Process SpawnProcess-11:
Traceback (most recent call last):
  File "/Applications/Xcode.app/Contents/Developer/Library/Frameworks/Python3.framework/Versions/3.9/lib/python3.9/multiprocessing/process.py", line 315, in _bootstrap
    self.run()
  File "/Applications/Xcode.app/Contents/Developer/Library/Frameworks/Python3.framework/Versions/3.9/lib/python3.9/multiprocessing/process.py", line 108, in run
    self._target(*self._args, **self._kwargs)
  File "/Users/juanpelos/Documents/.venv/lib/python3.9/site-packages/uvicorn/_subprocess.py", line 73, in subprocess_started
    sys.stdin = os.fdopen(stdin_fileno)  # pragma: full coverage
  File "/Applications/Xcode.app/Contents/Developer/Library/Frameworks/Python3.framework/Versions/3.9/lib/python3.9/os.py", line 1023, in fdopen
    return io.open(fd, *args, **kwargs)
OSError: [Errno 9] Bad file descriptor
INFO:     Will watch for changes in these directories: ['/Users/juanpelos/Documents/Data_Bases/Data_Bases_2.0/project_2/app']
ERROR:    [Errno 48] Address already in use

  You can now view your Streamlit app in your browser.

  Local URL: http://localhost:8508
  Network URL: http://192.168.2.12:8508

/Users/juanpelos/Documents/.venv/lib/python3.9/site-packages/urllib3/__init__.py:35: NotOpenSSLWarning: urllib3 v2 only supports OpenSSL 1.1.1+, currently the 'ssl' module is compiled with 'LibreSSL 2.8.3'. See: https://github.com/urllib3/urllib3/issues/3020
  warnings.warn(
WARNING:  WatchFiles detected changes in 'main.py'. Reloading...
Process SpawnProcess-12:
Traceback (most recent call last):
  File "/Applications/Xcode.app/Contents/Developer/Library/Frameworks/Python3.framework/Versions/3.9/lib/python3.9/multiprocessing/process.py", line 315, in _bootstrap
    self.run()
  File "/Applications/Xcode.app/Contents/Developer/Library/Frameworks/Python3.framework/Versions/3.9/lib/python3.9/multiprocessing/process.py", line 108, in run
    self._target(*self._args, **self._kwargs)
  File "/Users/juanpelos/Documents/.venv/lib/python3.9/site-packages/uvicorn/_subprocess.py", line 73, in subprocess_started
    sys.stdin = os.fdopen(stdin_fileno)  # pragma: full coverage
  File "/Applications/Xcode.app/Contents/Developer/Library/Frameworks/Python3.framework/Versions/3.9/lib/python3.9/os.py", line 1023, in fdopen
    return io.open(fd, *args, **kwargs)
OSError: [Errno 9] Bad file descriptor
WARNING:  WatchFiles detected changes in 'streamlit_app.py'. Reloading...
Process SpawnProcess-13:
Traceback (most recent call last):
  File "/Applications/Xcode.app/Contents/Developer/Library/Frameworks/Python3.framework/Versions/3.9/lib/python3.9/multiprocessing/process.py", line 315, in _bootstrap
    self.run()
  File "/Applications/Xcode.app/Contents/Developer/Library/Frameworks/Python3.framework/Versions/3.9/lib/python3.9/multiprocessing/process.py", line 108, in run
    self._target(*self._args, **self._kwargs)
  File "/Users/juanpelos/Documents/.venv/lib/python3.9/site-packages/uvicorn/_subprocess.py", line 73, in subprocess_started
    sys.stdin = os.fdopen(stdin_fileno)  # pragma: full coverage
  File "/Applications/Xcode.app/Contents/Developer/Library/Frameworks/Python3.framework/Versions/3.9/lib/python3.9/os.py", line 1023, in fdopen
    return io.open(fd, *args, **kwargs)
OSError: [Errno 9] Bad file descriptor
WARNING:  WatchFiles detected changes in 'streamlit_app.py'. Reloading...
Process SpawnProcess-14:
Traceback (most recent call last):
  File "/Applications/Xcode.app/Contents/Developer/Library/Frameworks/Python3.framework/Versions/3.9/lib/python3.9/multiprocessing/process.py", line 315, in _bootstrap
    self.run()
  File "/Applications/Xcode.app/Contents/Developer/Library/Frameworks/Python3.framework/Versions/3.9/lib/python3.9/multiprocessing/process.py", line 108, in run
    self._target(*self._args, **self._kwargs)
  File "/Users/juanpelos/Documents/.venv/lib/python3.9/site-packages/uvicorn/_subprocess.py", line 73, in subprocess_started
    sys.stdin = os.fdopen(stdin_fileno)  # pragma: full coverage
  File "/Applications/Xcode.app/Contents/Developer/Library/Frameworks/Python3.framework/Versions/3.9/lib/python3.9/os.py", line 1023, in fdopen
    return io.open(fd, *args, **kwargs)
OSError: [Errno 9] Bad file descriptor
WARNING:  WatchFiles detected changes in 'streamlit_app.py'. Reloading...
Process SpawnProcess-15:
Traceback (most recent call last):
  File "/Applications/Xcode.app/Contents/Developer/Library/Frameworks/Python3.framework/Versions/3.9/lib/python3.9/multiprocessing/process.py", line 315, in _bootstrap
    self.run()
  File "/Applications/Xcode.app/Contents/Developer/Library/Frameworks/Python3.framework/Versions/3.9/lib/python3.9/multiprocessing/process.py", line 108, in run
    self._target(*self._args, **self._kwargs)
  File "/Users/juanpelos/Documents/.venv/lib/python3.9/site-packages/uvicorn/_subprocess.py", line 73, in subprocess_started
    sys.stdin = os.fdopen(stdin_fileno)  # pragma: full coverage
  File "/Applications/Xcode.app/Contents/Developer/Library/Frameworks/Python3.framework/Versions/3.9/lib/python3.9/os.py", line 1023, in fdopen
    return io.open(fd, *args, **kwargs)
OSError: [Errno 9] Bad file descriptor
INFO:     Will watch for changes in these directories: ['/Users/juanpelos/Documents/Data_Bases/Data_Bases_2.0/project_2/app']
ERROR:    [Errno 48] Address already in use

  You can now view your Streamlit app in your browser.

  Local URL: http://localhost:8509
  Network URL: http://192.168.2.12:8509

/Users/juanpelos/Documents/.venv/lib/python3.9/site-packages/urllib3/__init__.py:35: NotOpenSSLWarning: urllib3 v2 only supports OpenSSL 1.1.1+, currently the 'ssl' module is compiled with 'LibreSSL 2.8.3'. See: https://github.com/urllib3/urllib3/issues/3020
  warnings.warn(
WARNING:  WatchFiles detected changes in 'main.py'. Reloading...
Process SpawnProcess-16:
Traceback (most recent call last):
  File "/Applications/Xcode.app/Contents/Developer/Library/Frameworks/Python3.framework/Versions/3.9/lib/python3.9/multiprocessing/process.py", line 315, in _bootstrap
    self.run()
  File "/Applications/Xcode.app/Contents/Developer/Library/Frameworks/Python3.framework/Versions/3.9/lib/python3.9/multiprocessing/process.py", line 108, in run
    self._target(*self._args, **self._kwargs)
  File "/Users/juanpelos/Documents/.venv/lib/python3.9/site-packages/uvicorn/_subprocess.py", line 73, in subprocess_started
    sys.stdin = os.fdopen(stdin_fileno)  # pragma: full coverage
  File "/Applications/Xcode.app/Contents/Developer/Library/Frameworks/Python3.framework/Versions/3.9/lib/python3.9/os.py", line 1023, in fdopen
    return io.open(fd, *args, **kwargs)
OSError: [Errno 9] Bad file descriptor
WARNING:  WatchFiles detected changes in 'streamlit_app.py'. Reloading...
Process SpawnProcess-17:
Traceback (most recent call last):
  File "/Applications/Xcode.app/Contents/Developer/Library/Frameworks/Python3.framework/Versions/3.9/lib/python3.9/multiprocessing/process.py", line 315, in _bootstrap
    self.run()
  File "/Applications/Xcode.app/Contents/Developer/Library/Frameworks/Python3.framework/Versions/3.9/lib/python3.9/multiprocessing/process.py", line 108, in run
    self._target(*self._args, **self._kwargs)
  File "/Users/juanpelos/Documents/.venv/lib/python3.9/site-packages/uvicorn/_subprocess.py", line 73, in subprocess_started
    sys.stdin = os.fdopen(stdin_fileno)  # pragma: full coverage
  File "/Applications/Xcode.app/Contents/Developer/Library/Frameworks/Python3.framework/Versions/3.9/lib/python3.9/os.py", line 1023, in fdopen
    return io.open(fd, *args, **kwargs)
OSError: [Errno 9] Bad file descriptor
INFO:     Will watch for changes in these directories: ['/Users/juanpelos/Documents/Data_Bases/Data_Bases_2.0/project_2/app']
ERROR:    [Errno 48] Address already in use

  You can now view your Streamlit app in your browser.

  Local URL: http://localhost:8510
  Network URL: http://192.168.2.12:8510

/Users/juanpelos/Documents/.venv/lib/python3.9/site-packages/urllib3/__init__.py:35: NotOpenSSLWarning: urllib3 v2 only supports OpenSSL 1.1.1+, currently the 'ssl' module is compiled with 'LibreSSL 2.8.3'. See: https://github.com/urllib3/urllib3/issues/3020
  warnings.warn(
WARNING:  WatchFiles detected changes in 'main.py'. Reloading...
Process SpawnProcess-18:
Traceback (most recent call last):
  File "/Applications/Xcode.app/Contents/Developer/Library/Frameworks/Python3.framework/Versions/3.9/lib/python3.9/multiprocessing/process.py", line 315, in _bootstrap
    self.run()
  File "/Applications/Xcode.app/Contents/Developer/Library/Frameworks/Python3.framework/Versions/3.9/lib/python3.9/multiprocessing/process.py", line 108, in run
    self._target(*self._args, **self._kwargs)
  File "/Users/juanpelos/Documents/.venv/lib/python3.9/site-packages/uvicorn/_subprocess.py", line 73, in subprocess_started
    sys.stdin = os.fdopen(stdin_fileno)  # pragma: full coverage
  File "/Applications/Xcode.app/Contents/Developer/Library/Frameworks/Python3.framework/Versions/3.9/lib/python3.9/os.py", line 1023, in fdopen
    return io.open(fd, *args, **kwargs)
OSError: [Errno 9] Bad file descriptor
WARNING:  WatchFiles detected changes in 'streamlit_app.py'. Reloading...
Process SpawnProcess-19:
Traceback (most recent call last):
  File "/Applications/Xcode.app/Contents/Developer/Library/Frameworks/Python3.framework/Versions/3.9/lib/python3.9/multiprocessing/process.py", line 315, in _bootstrap
    self.run()
  File "/Applications/Xcode.app/Contents/Developer/Library/Frameworks/Python3.framework/Versions/3.9/lib/python3.9/multiprocessing/process.py", line 108, in run
    self._target(*self._args, **self._kwargs)
  File "/Users/juanpelos/Documents/.venv/lib/python3.9/site-packages/uvicorn/_subprocess.py", line 73, in subprocess_started
    sys.stdin = os.fdopen(stdin_fileno)  # pragma: full coverage
  File "/Applications/Xcode.app/Contents/Developer/Library/Frameworks/Python3.framework/Versions/3.9/lib/python3.9/os.py", line 1023, in fdopen
    return io.open(fd, *args, **kwargs)
OSError: [Errno 9] Bad file descriptor
/Users/juanpelos/Documents/Data_Bases/Data_Bases_2.0/project_2/app/streamlit_app.py:41: UserWarning: Could not infer format, so each element will be parsed individually, falling back to `dateutil`. To ensure parsing is consistent and as-expected, please specify a format.
  # Funci√≥n para limpiar todos los registros de una tabla
/Users/juanpelos/Documents/Data_Bases/Data_Bases_2.0/project_2/app/streamlit_app.py:41: UserWarning: Could not infer format, so each element will be parsed individually, falling back to `dateutil`. To ensure parsing is consistent and as-expected, please specify a format.
  # Funci√≥n para limpiar todos los registros de una tabla
/Users/juanpelos/Documents/Data_Bases/Data_Bases_2.0/project_2/app/streamlit_app.py:41: UserWarning: Could not infer format, so each element will be parsed individually, falling back to `dateutil`. To ensure parsing is consistent and as-expected, please specify a format.
  # Funci√≥n para limpiar todos los registros de una tabla
/Users/juanpelos/Documents/Data_Bases/Data_Bases_2.0/project_2/app/streamlit_app.py:41: UserWarning: Could not infer format, so each element will be parsed individually, falling back to `dateutil`. To ensure parsing is consistent and as-expected, please specify a format.
  # Funci√≥n para limpiar todos los registros de una tabla
/Users/juanpelos/Documents/Data_Bases/Data_Bases_2.0/project_2/app/streamlit_app.py:41: UserWarning: Could not infer format, so each element will be parsed individually, falling back to `dateutil`. To ensure parsing is consistent and as-expected, please specify a format.
  # Funci√≥n para limpiar todos los registros de una tabla
WARNING:  WatchFiles detected changes in 'streamlit_app.py'. Reloading...
Process SpawnProcess-20:
Traceback (most recent call last):
  File "/Applications/Xcode.app/Contents/Developer/Library/Frameworks/Python3.framework/Versions/3.9/lib/python3.9/multiprocessing/process.py", line 315, in _bootstrap
    self.run()
  File "/Applications/Xcode.app/Contents/Developer/Library/Frameworks/Python3.framework/Versions/3.9/lib/python3.9/multiprocessing/process.py", line 108, in run
    self._target(*self._args, **self._kwargs)
  File "/Users/juanpelos/Documents/.venv/lib/python3.9/site-packages/uvicorn/_subprocess.py", line 73, in subprocess_started
    sys.stdin = os.fdopen(stdin_fileno)  # pragma: full coverage
  File "/Applications/Xcode.app/Contents/Developer/Library/Frameworks/Python3.framework/Versions/3.9/lib/python3.9/os.py", line 1023, in fdopen
    return io.open(fd, *args, **kwargs)
OSError: [Errno 9] Bad file descriptor
WARNING:  WatchFiles detected changes in 'streamlit_app.py'. Reloading...
Process SpawnProcess-21:
Traceback (most recent call last):
  File "/Applications/Xcode.app/Contents/Developer/Library/Frameworks/Python3.framework/Versions/3.9/lib/python3.9/multiprocessing/process.py", line 315, in _bootstrap
    self.run()
  File "/Applications/Xcode.app/Contents/Developer/Library/Frameworks/Python3.framework/Versions/3.9/lib/python3.9/multiprocessing/process.py", line 108, in run
    self._target(*self._args, **self._kwargs)
  File "/Users/juanpelos/Documents/.venv/lib/python3.9/site-packages/uvicorn/_subprocess.py", line 73, in subprocess_started
    sys.stdin = os.fdopen(stdin_fileno)  # pragma: full coverage
  File "/Applications/Xcode.app/Contents/Developer/Library/Frameworks/Python3.framework/Versions/3.9/lib/python3.9/os.py", line 1023, in fdopen
    return io.open(fd, *args, **kwargs)
OSError: [Errno 9] Bad file descriptor
WARNING:  WatchFiles detected changes in 'main.py'. Reloading...
Process SpawnProcess-22:
Traceback (most recent call last):
  File "/Applications/Xcode.app/Contents/Developer/Library/Frameworks/Python3.framework/Versions/3.9/lib/python3.9/multiprocessing/process.py", line 315, in _bootstrap
    self.run()
  File "/Applications/Xcode.app/Contents/Developer/Library/Frameworks/Python3.framework/Versions/3.9/lib/python3.9/multiprocessing/process.py", line 108, in run
    self._target(*self._args, **self._kwargs)
  File "/Users/juanpelos/Documents/.venv/lib/python3.9/site-packages/uvicorn/_subprocess.py", line 73, in subprocess_started
    sys.stdin = os.fdopen(stdin_fileno)  # pragma: full coverage
  File "/Applications/Xcode.app/Contents/Developer/Library/Frameworks/Python3.framework/Versions/3.9/lib/python3.9/os.py", line 1023, in fdopen
    return io.open(fd, *args, **kwargs)
OSError: [Errno 9] Bad file descriptor
/Users/juanpelos/Documents/Data_Bases/Data_Bases_2.0/project_2/app/streamlit_app.py:45: UserWarning: Could not infer format, so each element will be parsed individually, falling back to `dateutil`. To ensure parsing is consistent and as-expected, please specify a format.
  st.success(f"Todos los registros de {table} han sido eliminados.")
/Users/juanpelos/Documents/Data_Bases/Data_Bases_2.0/project_2/app/streamlit_app.py:45: UserWarning: Could not infer format, so each element will be parsed individually, falling back to `dateutil`. To ensure parsing is consistent and as-expected, please specify a format.
  st.success(f"Todos los registros de {table} han sido eliminados.")
/Users/juanpelos/Documents/Data_Bases/Data_Bases_2.0/project_2/app/streamlit_app.py:45: UserWarning: Could not infer format, so each element will be parsed individually, falling back to `dateutil`. To ensure parsing is consistent and as-expected, please specify a format.
  st.success(f"Todos los registros de {table} han sido eliminados.")
/Users/juanpelos/Documents/Data_Bases/Data_Bases_2.0/project_2/app/streamlit_app.py:45: UserWarning: Could not infer format, so each element will be parsed individually, falling back to `dateutil`. To ensure parsing is consistent and as-expected, please specify a format.
  st.success(f"Todos los registros de {table} han sido eliminados.")
/Users/juanpelos/Documents/Data_Bases/Data_Bases_2.0/project_2/app/streamlit_app.py:45: UserWarning: Could not infer format, so each element will be parsed individually, falling back to `dateutil`. To ensure parsing is consistent and as-expected, please specify a format.
  st.success(f"Todos los registros de {table} han sido eliminados.")
/Users/juanpelos/Documents/Data_Bases/Data_Bases_2.0/project_2/app/streamlit_app.py:45: UserWarning: Could not infer format, so each element will be parsed individually, falling back to `dateutil`. To ensure parsing is consistent and as-expected, please specify a format.
  st.success(f"Todos los registros de {table} han sido eliminados.")
/Users/juanpelos/Documents/Data_Bases/Data_Bases_2.0/project_2/app/streamlit_app.py:45: UserWarning: Could not infer format, so each element will be parsed individually, falling back to `dateutil`. To ensure parsing is consistent and as-expected, please specify a format.
  st.success(f"Todos los registros de {table} han sido eliminados.")
/Users/juanpelos/Documents/Data_Bases/Data_Bases_2.0/project_2/app/streamlit_app.py:45: UserWarning: Could not infer format, so each element will be parsed individually, falling back to `dateutil`. To ensure parsing is consistent and as-expected, please specify a format.
  st.success(f"Todos los registros de {table} han sido eliminados.")
/Users/juanpelos/Documents/Data_Bases/Data_Bases_2.0/project_2/app/streamlit_app.py:45: UserWarning: Could not infer format, so each element will be parsed individually, falling back to `dateutil`. To ensure parsing is consistent and as-expected, please specify a format.
  st.success(f"Todos los registros de {table} han sido eliminados.")
/Users/juanpelos/Documents/Data_Bases/Data_Bases_2.0/project_2/app/streamlit_app.py:45: UserWarning: Could not infer format, so each element will be parsed individually, falling back to `dateutil`. To ensure parsing is consistent and as-expected, please specify a format.
  st.success(f"Todos los registros de {table} han sido eliminados.")
WARNING:  WatchFiles detected changes in 'main.py'. Reloading...
Process SpawnProcess-23:
Traceback (most recent call last):
  File "/Applications/Xcode.app/Contents/Developer/Library/Frameworks/Python3.framework/Versions/3.9/lib/python3.9/multiprocessing/process.py", line 315, in _bootstrap
    self.run()
  File "/Applications/Xcode.app/Contents/Developer/Library/Frameworks/Python3.framework/Versions/3.9/lib/python3.9/multiprocessing/process.py", line 108, in run
    self._target(*self._args, **self._kwargs)
  File "/Users/juanpelos/Documents/.venv/lib/python3.9/site-packages/uvicorn/_subprocess.py", line 73, in subprocess_started
    sys.stdin = os.fdopen(stdin_fileno)  # pragma: full coverage
  File "/Applications/Xcode.app/Contents/Developer/Library/Frameworks/Python3.framework/Versions/3.9/lib/python3.9/os.py", line 1023, in fdopen
    return io.open(fd, *args, **kwargs)
OSError: [Errno 9] Bad file descriptor
/Users/juanpelos/Documents/Data_Bases/Data_Bases_2.0/project_2/app/streamlit_app.py:45: UserWarning: Could not infer format, so each element will be parsed individually, falling back to `dateutil`. To ensure parsing is consistent and as-expected, please specify a format.
  st.success(f"Todos los registros de {table} han sido eliminados.")
/Users/juanpelos/Documents/Data_Bases/Data_Bases_2.0/project_2/app/streamlit_app.py:45: UserWarning: Could not infer format, so each element will be parsed individually, falling back to `dateutil`. To ensure parsing is consistent and as-expected, please specify a format.
  st.success(f"Todos los registros de {table} han sido eliminados.")
/Users/juanpelos/Documents/Data_Bases/Data_Bases_2.0/project_2/app/streamlit_app.py:45: UserWarning: Could not infer format, so each element will be parsed individually, falling back to `dateutil`. To ensure parsing is consistent and as-expected, please specify a format.
  st.success(f"Todos los registros de {table} han sido eliminados.")
/Users/juanpelos/Documents/Data_Bases/Data_Bases_2.0/project_2/app/streamlit_app.py:45: UserWarning: Could not infer format, so each element will be parsed individually, falling back to `dateutil`. To ensure parsing is consistent and as-expected, please specify a format.
  st.success(f"Todos los registros de {table} han sido eliminados.")
/Users/juanpelos/Documents/Data_Bases/Data_Bases_2.0/project_2/app/streamlit_app.py:45: UserWarning: Could not infer format, so each element will be parsed individually, falling back to `dateutil`. To ensure parsing is consistent and as-expected, please specify a format.
  st.success(f"Todos los registros de {table} han sido eliminados.")
WARNING:  WatchFiles detected changes in 'main.py'. Reloading...
Process SpawnProcess-24:
Traceback (most recent call last):
  File "/Applications/Xcode.app/Contents/Developer/Library/Frameworks/Python3.framework/Versions/3.9/lib/python3.9/multiprocessing/process.py", line 315, in _bootstrap
    self.run()
  File "/Applications/Xcode.app/Contents/Developer/Library/Frameworks/Python3.framework/Versions/3.9/lib/python3.9/multiprocessing/process.py", line 108, in run
    self._target(*self._args, **self._kwargs)
  File "/Users/juanpelos/Documents/.venv/lib/python3.9/site-packages/uvicorn/_subprocess.py", line 73, in subprocess_started
    sys.stdin = os.fdopen(stdin_fileno)  # pragma: full coverage
  File "/Applications/Xcode.app/Contents/Developer/Library/Frameworks/Python3.framework/Versions/3.9/lib/python3.9/os.py", line 1023, in fdopen
    return io.open(fd, *args, **kwargs)
OSError: [Errno 9] Bad file descriptor
WARNING:  WatchFiles detected changes in 'streamlit_app.py'. Reloading...
Process SpawnProcess-25:
Traceback (most recent call last):
  File "/Applications/Xcode.app/Contents/Developer/Library/Frameworks/Python3.framework/Versions/3.9/lib/python3.9/multiprocessing/process.py", line 315, in _bootstrap
    self.run()
  File "/Applications/Xcode.app/Contents/Developer/Library/Frameworks/Python3.framework/Versions/3.9/lib/python3.9/multiprocessing/process.py", line 108, in run
    self._target(*self._args, **self._kwargs)
  File "/Users/juanpelos/Documents/.venv/lib/python3.9/site-packages/uvicorn/_subprocess.py", line 73, in subprocess_started
    sys.stdin = os.fdopen(stdin_fileno)  # pragma: full coverage
  File "/Applications/Xcode.app/Contents/Developer/Library/Frameworks/Python3.framework/Versions/3.9/lib/python3.9/os.py", line 1023, in fdopen
    return io.open(fd, *args, **kwargs)
OSError: [Errno 9] Bad file descriptor
WARNING:  WatchFiles detected changes in 'streamlit_app.py'. Reloading...
Process SpawnProcess-26:
Traceback (most recent call last):
  File "/Applications/Xcode.app/Contents/Developer/Library/Frameworks/Python3.framework/Versions/3.9/lib/python3.9/multiprocessing/process.py", line 315, in _bootstrap
    self.run()
  File "/Applications/Xcode.app/Contents/Developer/Library/Frameworks/Python3.framework/Versions/3.9/lib/python3.9/multiprocessing/process.py", line 108, in run
    self._target(*self._args, **self._kwargs)
  File "/Users/juanpelos/Documents/.venv/lib/python3.9/site-packages/uvicorn/_subprocess.py", line 73, in subprocess_started
    sys.stdin = os.fdopen(stdin_fileno)  # pragma: full coverage
  File "/Applications/Xcode.app/Contents/Developer/Library/Frameworks/Python3.framework/Versions/3.9/lib/python3.9/os.py", line 1023, in fdopen
    return io.open(fd, *args, **kwargs)
OSError: [Errno 9] Bad file descriptor
WARNING:  WatchFiles detected changes in 'main.py'. Reloading...
Process SpawnProcess-27:
Traceback (most recent call last):
  File "/Applications/Xcode.app/Contents/Developer/Library/Frameworks/Python3.framework/Versions/3.9/lib/python3.9/multiprocessing/process.py", line 315, in _bootstrap
    self.run()
  File "/Applications/Xcode.app/Contents/Developer/Library/Frameworks/Python3.framework/Versions/3.9/lib/python3.9/multiprocessing/process.py", line 108, in run
    self._target(*self._args, **self._kwargs)
  File "/Users/juanpelos/Documents/.venv/lib/python3.9/site-packages/uvicorn/_subprocess.py", line 73, in subprocess_started
    sys.stdin = os.fdopen(stdin_fileno)  # pragma: full coverage
  File "/Applications/Xcode.app/Contents/Developer/Library/Frameworks/Python3.framework/Versions/3.9/lib/python3.9/os.py", line 1023, in fdopen
    return io.open(fd, *args, **kwargs)
OSError: [Errno 9] Bad file descriptor
2024-11-07 19:48:15.295 Uncaught app exception
Traceback (most recent call last):
  File "/Users/juanpelos/Documents/.venv/lib/python3.9/site-packages/requests/models.py", line 974, in json
    return complexjson.loads(self.text, **kwargs)
  File "/Applications/Xcode.app/Contents/Developer/Library/Frameworks/Python3.framework/Versions/3.9/lib/python3.9/json/__init__.py", line 346, in loads
    return _default_decoder.decode(s)
  File "/Applications/Xcode.app/Contents/Developer/Library/Frameworks/Python3.framework/Versions/3.9/lib/python3.9/json/decoder.py", line 337, in decode
    obj, end = self.raw_decode(s, idx=_w(s, 0).end())
  File "/Applications/Xcode.app/Contents/Developer/Library/Frameworks/Python3.framework/Versions/3.9/lib/python3.9/json/decoder.py", line 355, in raw_decode
    raise JSONDecodeError("Expecting value", s, err.value) from None
json.decoder.JSONDecodeError: Expecting value: line 1 column 1 (char 0)

During handling of the above exception, another exception occurred:

Traceback (most recent call last):
  File "/Users/juanpelos/Documents/.venv/lib/python3.9/site-packages/streamlit/runtime/scriptrunner/exec_code.py", line 88, in exec_func_with_error_handling
    result = func()
  File "/Users/juanpelos/Documents/.venv/lib/python3.9/site-packages/streamlit/runtime/scriptrunner/script_runner.py", line 590, in code_to_exec
    exec(code, module.__dict__)
  File "/Users/juanpelos/Documents/Data_Bases/Data_Bases_2.0/project_2/app/streamlit_app.py", line 130, in <module>
    st.error(f"Error: {response.json().get('detail', 'Consulta SQL no v√°lida')}")
  File "/Users/juanpelos/Documents/.venv/lib/python3.9/site-packages/requests/models.py", line 978, in json
    raise RequestsJSONDecodeError(e.msg, e.doc, e.pos)
requests.exceptions.JSONDecodeError: Expecting value: line 1 column 1 (char 0)
WARNING:  WatchFiles detected changes in 'main.py'. Reloading...
Process SpawnProcess-28:
Traceback (most recent call last):
  File "/Applications/Xcode.app/Contents/Developer/Library/Frameworks/Python3.framework/Versions/3.9/lib/python3.9/multiprocessing/process.py", line 315, in _bootstrap
    self.run()
  File "/Applications/Xcode.app/Contents/Developer/Library/Frameworks/Python3.framework/Versions/3.9/lib/python3.9/multiprocessing/process.py", line 108, in run
    self._target(*self._args, **self._kwargs)
  File "/Users/juanpelos/Documents/.venv/lib/python3.9/site-packages/uvicorn/_subprocess.py", line 73, in subprocess_started
    sys.stdin = os.fdopen(stdin_fileno)  # pragma: full coverage
  File "/Applications/Xcode.app/Contents/Developer/Library/Frameworks/Python3.framework/Versions/3.9/lib/python3.9/os.py", line 1023, in fdopen
    return io.open(fd, *args, **kwargs)
OSError: [Errno 9] Bad file descriptor
WARNING:  WatchFiles detected changes in 'streamlit_app.py'. Reloading...
Process SpawnProcess-29:
Traceback (most recent call last):
  File "/Applications/Xcode.app/Contents/Developer/Library/Frameworks/Python3.framework/Versions/3.9/lib/python3.9/multiprocessing/process.py", line 315, in _bootstrap
    self.run()
  File "/Applications/Xcode.app/Contents/Developer/Library/Frameworks/Python3.framework/Versions/3.9/lib/python3.9/multiprocessing/process.py", line 108, in run
    self._target(*self._args, **self._kwargs)
  File "/Users/juanpelos/Documents/.venv/lib/python3.9/site-packages/uvicorn/_subprocess.py", line 73, in subprocess_started
    sys.stdin = os.fdopen(stdin_fileno)  # pragma: full coverage
  File "/Applications/Xcode.app/Contents/Developer/Library/Frameworks/Python3.framework/Versions/3.9/lib/python3.9/os.py", line 1023, in fdopen
    return io.open(fd, *args, **kwargs)
OSError: [Errno 9] Bad file descriptor
2024-11-07 19:58:25.519 Uncaught app exception
Traceback (most recent call last):
  File "/Users/juanpelos/Documents/.venv/lib/python3.9/site-packages/requests/models.py", line 974, in json
    return complexjson.loads(self.text, **kwargs)
  File "/Applications/Xcode.app/Contents/Developer/Library/Frameworks/Python3.framework/Versions/3.9/lib/python3.9/json/__init__.py", line 346, in loads
    return _default_decoder.decode(s)
  File "/Applications/Xcode.app/Contents/Developer/Library/Frameworks/Python3.framework/Versions/3.9/lib/python3.9/json/decoder.py", line 337, in decode
    obj, end = self.raw_decode(s, idx=_w(s, 0).end())
  File "/Applications/Xcode.app/Contents/Developer/Library/Frameworks/Python3.framework/Versions/3.9/lib/python3.9/json/decoder.py", line 355, in raw_decode
    raise JSONDecodeError("Expecting value", s, err.value) from None
json.decoder.JSONDecodeError: Expecting value: line 1 column 1 (char 0)

During handling of the above exception, another exception occurred:

Traceback (most recent call last):
  File "/Users/juanpelos/Documents/.venv/lib/python3.9/site-packages/streamlit/runtime/scriptrunner/exec_code.py", line 88, in exec_func_with_error_handling
    result = func()
  File "/Users/juanpelos/Documents/.venv/lib/python3.9/site-packages/streamlit/runtime/scriptrunner/script_runner.py", line 590, in code_to_exec
    exec(code, module.__dict__)
  File "/Users/juanpelos/Documents/Data_Bases/Data_Bases_2.0/project_2/app/streamlit_app.py", line 130, in <module>
    st.error(f"Error: {response.json().get('detail', 'Consulta SQL no v√°lida')}")
  File "/Users/juanpelos/Documents/.venv/lib/python3.9/site-packages/requests/models.py", line 978, in json
    raise RequestsJSONDecodeError(e.msg, e.doc, e.pos)
requests.exceptions.JSONDecodeError: Expecting value: line 1 column 1 (char 0)
WARNING:  WatchFiles detected changes in 'streamlit_app.py'. Reloading...
Process SpawnProcess-30:
Traceback (most recent call last):
  File "/Applications/Xcode.app/Contents/Developer/Library/Frameworks/Python3.framework/Versions/3.9/lib/python3.9/multiprocessing/process.py", line 315, in _bootstrap
    self.run()
  File "/Applications/Xcode.app/Contents/Developer/Library/Frameworks/Python3.framework/Versions/3.9/lib/python3.9/multiprocessing/process.py", line 108, in run
    self._target(*self._args, **self._kwargs)
  File "/Users/juanpelos/Documents/.venv/lib/python3.9/site-packages/uvicorn/_subprocess.py", line 73, in subprocess_started
    sys.stdin = os.fdopen(stdin_fileno)  # pragma: full coverage
  File "/Applications/Xcode.app/Contents/Developer/Library/Frameworks/Python3.framework/Versions/3.9/lib/python3.9/os.py", line 1023, in fdopen
    return io.open(fd, *args, **kwargs)
OSError: [Errno 9] Bad file descriptor
WARNING:  WatchFiles detected changes in 'main.py'. Reloading...
Process SpawnProcess-31:
Traceback (most recent call last):
  File "/Applications/Xcode.app/Contents/Developer/Library/Frameworks/Python3.framework/Versions/3.9/lib/python3.9/multiprocessing/process.py", line 315, in _bootstrap
    self.run()
  File "/Applications/Xcode.app/Contents/Developer/Library/Frameworks/Python3.framework/Versions/3.9/lib/python3.9/multiprocessing/process.py", line 108, in run
    self._target(*self._args, **self._kwargs)
  File "/Users/juanpelos/Documents/.venv/lib/python3.9/site-packages/uvicorn/_subprocess.py", line 73, in subprocess_started
    sys.stdin = os.fdopen(stdin_fileno)  # pragma: full coverage
  File "/Applications/Xcode.app/Contents/Developer/Library/Frameworks/Python3.framework/Versions/3.9/lib/python3.9/os.py", line 1023, in fdopen
    return io.open(fd, *args, **kwargs)
OSError: [Errno 9] Bad file descriptor
WARNING:  WatchFiles detected changes in 'main.py'. Reloading...
Process SpawnProcess-32:
Traceback (most recent call last):
  File "/Applications/Xcode.app/Contents/Developer/Library/Frameworks/Python3.framework/Versions/3.9/lib/python3.9/multiprocessing/process.py", line 315, in _bootstrap
    self.run()
  File "/Applications/Xcode.app/Contents/Developer/Library/Frameworks/Python3.framework/Versions/3.9/lib/python3.9/multiprocessing/process.py", line 108, in run
    self._target(*self._args, **self._kwargs)
  File "/Users/juanpelos/Documents/.venv/lib/python3.9/site-packages/uvicorn/_subprocess.py", line 73, in subprocess_started
    sys.stdin = os.fdopen(stdin_fileno)  # pragma: full coverage
  File "/Applications/Xcode.app/Contents/Developer/Library/Frameworks/Python3.framework/Versions/3.9/lib/python3.9/os.py", line 1023, in fdopen
    return io.open(fd, *args, **kwargs)
OSError: [Errno 9] Bad file descriptor
WARNING:  WatchFiles detected changes in 'main.py'. Reloading...
Process SpawnProcess-33:
Traceback (most recent call last):
  File "/Applications/Xcode.app/Contents/Developer/Library/Frameworks/Python3.framework/Versions/3.9/lib/python3.9/multiprocessing/process.py", line 315, in _bootstrap
    self.run()
  File "/Applications/Xcode.app/Contents/Developer/Library/Frameworks/Python3.framework/Versions/3.9/lib/python3.9/multiprocessing/process.py", line 108, in run
    self._target(*self._args, **self._kwargs)
  File "/Users/juanpelos/Documents/.venv/lib/python3.9/site-packages/uvicorn/_subprocess.py", line 73, in subprocess_started
    sys.stdin = os.fdopen(stdin_fileno)  # pragma: full coverage
  File "/Applications/Xcode.app/Contents/Developer/Library/Frameworks/Python3.framework/Versions/3.9/lib/python3.9/os.py", line 1023, in fdopen
    return io.open(fd, *args, **kwargs)
OSError: [Errno 9] Bad file descriptor
/Users/juanpelos/Documents/Data_Bases/Data_Bases_2.0/project_2/app/streamlit_app.py:49: UserWarning: Could not infer format, so each element will be parsed individually, falling back to `dateutil`. To ensure parsing is consistent and as-expected, please specify a format.
  if mode == "Usuario":
/Users/juanpelos/Documents/Data_Bases/Data_Bases_2.0/project_2/app/streamlit_app.py:49: UserWarning: Could not infer format, so each element will be parsed individually, falling back to `dateutil`. To ensure parsing is consistent and as-expected, please specify a format.
  if mode == "Usuario":
/Users/juanpelos/Documents/Data_Bases/Data_Bases_2.0/project_2/app/streamlit_app.py:49: UserWarning: Could not infer format, so each element will be parsed individually, falling back to `dateutil`. To ensure parsing is consistent and as-expected, please specify a format.
  if mode == "Usuario":
/Users/juanpelos/Documents/Data_Bases/Data_Bases_2.0/project_2/app/streamlit_app.py:49: UserWarning: Could not infer format, so each element will be parsed individually, falling back to `dateutil`. To ensure parsing is consistent and as-expected, please specify a format.
  if mode == "Usuario":
/Users/juanpelos/Documents/Data_Bases/Data_Bases_2.0/project_2/app/streamlit_app.py:49: UserWarning: Could not infer format, so each element will be parsed individually, falling back to `dateutil`. To ensure parsing is consistent and as-expected, please specify a format.
  if mode == "Usuario":
/Users/juanpelos/Documents/Data_Bases/Data_Bases_2.0/project_2/app/streamlit_app.py:49: UserWarning: Could not infer format, so each element will be parsed individually, falling back to `dateutil`. To ensure parsing is consistent and as-expected, please specify a format.
  if mode == "Usuario":
/Users/juanpelos/Documents/Data_Bases/Data_Bases_2.0/project_2/app/streamlit_app.py:49: UserWarning: Could not infer format, so each element will be parsed individually, falling back to `dateutil`. To ensure parsing is consistent and as-expected, please specify a format.
  if mode == "Usuario":
/Users/juanpelos/Documents/Data_Bases/Data_Bases_2.0/project_2/app/streamlit_app.py:49: UserWarning: Could not infer format, so each element will be parsed individually, falling back to `dateutil`. To ensure parsing is consistent and as-expected, please specify a format.
  if mode == "Usuario":
/Users/juanpelos/Documents/Data_Bases/Data_Bases_2.0/project_2/app/streamlit_app.py:49: UserWarning: Could not infer format, so each element will be parsed individually, falling back to `dateutil`. To ensure parsing is consistent and as-expected, please specify a format.
  if mode == "Usuario":
/Users/juanpelos/Documents/Data_Bases/Data_Bases_2.0/project_2/app/streamlit_app.py:49: UserWarning: Could not infer format, so each element will be parsed individually, falling back to `dateutil`. To ensure parsing is consistent and as-expected, please specify a format.
  if mode == "Usuario":
/Users/juanpelos/Documents/Data_Bases/Data_Bases_2.0/project_2/app/streamlit_app.py:49: UserWarning: Could not infer format, so each element will be parsed individually, falling back to `dateutil`. To ensure parsing is consistent and as-expected, please specify a format.
  if mode == "Usuario":
/Users/juanpelos/Documents/Data_Bases/Data_Bases_2.0/project_2/app/streamlit_app.py:49: UserWarning: Could not infer format, so each element will be parsed individually, falling back to `dateutil`. To ensure parsing is consistent and as-expected, please specify a format.
  if mode == "Usuario":
/Users/juanpelos/Documents/Data_Bases/Data_Bases_2.0/project_2/app/streamlit_app.py:49: UserWarning: Could not infer format, so each element will be parsed individually, falling back to `dateutil`. To ensure parsing is consistent and as-expected, please specify a format.
  if mode == "Usuario":
/Users/juanpelos/Documents/Data_Bases/Data_Bases_2.0/project_2/app/streamlit_app.py:49: UserWarning: Could not infer format, so each element will be parsed individually, falling back to `dateutil`. To ensure parsing is consistent and as-expected, please specify a format.
  if mode == "Usuario":
/Users/juanpelos/Documents/Data_Bases/Data_Bases_2.0/project_2/app/streamlit_app.py:49: UserWarning: Could not infer format, so each element will be parsed individually, falling back to `dateutil`. To ensure parsing is consistent and as-expected, please specify a format.
  if mode == "Usuario":
/Users/juanpelos/Documents/Data_Bases/Data_Bases_2.0/project_2/app/streamlit_app.py:49: UserWarning: Could not infer format, so each element will be parsed individually, falling back to `dateutil`. To ensure parsing is consistent and as-expected, please specify a format.
  if mode == "Usuario":
/Users/juanpelos/Documents/Data_Bases/Data_Bases_2.0/project_2/app/streamlit_app.py:49: UserWarning: Could not infer format, so each element will be parsed individually, falling back to `dateutil`. To ensure parsing is consistent and as-expected, please specify a format.
  if mode == "Usuario":
/Users/juanpelos/Documents/Data_Bases/Data_Bases_2.0/project_2/app/streamlit_app.py:49: UserWarning: Could not infer format, so each element will be parsed individually, falling back to `dateutil`. To ensure parsing is consistent and as-expected, please specify a format.
  if mode == "Usuario":
/Users/juanpelos/Documents/Data_Bases/Data_Bases_2.0/project_2/app/streamlit_app.py:49: UserWarning: Could not infer format, so each element will be parsed individually, falling back to `dateutil`. To ensure parsing is consistent and as-expected, please specify a format.
  if mode == "Usuario":
/Users/juanpelos/Documents/Data_Bases/Data_Bases_2.0/project_2/app/streamlit_app.py:49: UserWarning: Could not infer format, so each element will be parsed individually, falling back to `dateutil`. To ensure parsing is consistent and as-expected, please specify a format.
  if mode == "Usuario":
/Users/juanpelos/Documents/Data_Bases/Data_Bases_2.0/project_2/app/streamlit_app.py:49: UserWarning: Could not infer format, so each element will be parsed individually, falling back to `dateutil`. To ensure parsing is consistent and as-expected, please specify a format.
  if mode == "Usuario":
/Users/juanpelos/Documents/Data_Bases/Data_Bases_2.0/project_2/app/streamlit_app.py:49: UserWarning: Could not infer format, so each element will be parsed individually, falling back to `dateutil`. To ensure parsing is consistent and as-expected, please specify a format.
  if mode == "Usuario":
/Users/juanpelos/Documents/Data_Bases/Data_Bases_2.0/project_2/app/streamlit_app.py:49: UserWarning: Could not infer format, so each element will be parsed individually, falling back to `dateutil`. To ensure parsing is consistent and as-expected, please specify a format.
  if mode == "Usuario":
/Users/juanpelos/Documents/Data_Bases/Data_Bases_2.0/project_2/app/streamlit_app.py:49: UserWarning: Could not infer format, so each element will be parsed individually, falling back to `dateutil`. To ensure parsing is consistent and as-expected, please specify a format.
  if mode == "Usuario":
/Users/juanpelos/Documents/Data_Bases/Data_Bases_2.0/project_2/app/streamlit_app.py:49: UserWarning: Could not infer format, so each element will be parsed individually, falling back to `dateutil`. To ensure parsing is consistent and as-expected, please specify a format.
  if mode == "Usuario":
/Users/juanpelos/Documents/Data_Bases/Data_Bases_2.0/project_2/app/streamlit_app.py:49: UserWarning: Could not infer format, so each element will be parsed individually, falling back to `dateutil`. To ensure parsing is consistent and as-expected, please specify a format.
  if mode == "Usuario":
WARNING:  WatchFiles detected changes in 'main.py'. Reloading...
Process SpawnProcess-34:
Traceback (most recent call last):
  File "/Applications/Xcode.app/Contents/Developer/Library/Frameworks/Python3.framework/Versions/3.9/lib/python3.9/multiprocessing/process.py", line 315, in _bootstrap
    self.run()
  File "/Applications/Xcode.app/Contents/Developer/Library/Frameworks/Python3.framework/Versions/3.9/lib/python3.9/multiprocessing/process.py", line 108, in run
    self._target(*self._args, **self._kwargs)
  File "/Users/juanpelos/Documents/.venv/lib/python3.9/site-packages/uvicorn/_subprocess.py", line 73, in subprocess_started
    sys.stdin = os.fdopen(stdin_fileno)  # pragma: full coverage
  File "/Applications/Xcode.app/Contents/Developer/Library/Frameworks/Python3.framework/Versions/3.9/lib/python3.9/os.py", line 1023, in fdopen
    return io.open(fd, *args, **kwargs)
OSError: [Errno 9] Bad file descriptor
WARNING:  WatchFiles detected changes in 'streamlit_app.py'. Reloading...
Process SpawnProcess-35:
Traceback (most recent call last):
  File "/Applications/Xcode.app/Contents/Developer/Library/Frameworks/Python3.framework/Versions/3.9/lib/python3.9/multiprocessing/process.py", line 315, in _bootstrap
    self.run()
  File "/Applications/Xcode.app/Contents/Developer/Library/Frameworks/Python3.framework/Versions/3.9/lib/python3.9/multiprocessing/process.py", line 108, in run
    self._target(*self._args, **self._kwargs)
  File "/Users/juanpelos/Documents/.venv/lib/python3.9/site-packages/uvicorn/_subprocess.py", line 73, in subprocess_started
    sys.stdin = os.fdopen(stdin_fileno)  # pragma: full coverage
  File "/Applications/Xcode.app/Contents/Developer/Library/Frameworks/Python3.framework/Versions/3.9/lib/python3.9/os.py", line 1023, in fdopen
    return io.open(fd, *args, **kwargs)
OSError: [Errno 9] Bad file descriptor
WARNING:  WatchFiles detected changes in 'main.py'. Reloading...
Process SpawnProcess-36:
Traceback (most recent call last):
  File "/Applications/Xcode.app/Contents/Developer/Library/Frameworks/Python3.framework/Versions/3.9/lib/python3.9/multiprocessing/process.py", line 315, in _bootstrap
    self.run()
  File "/Applications/Xcode.app/Contents/Developer/Library/Frameworks/Python3.framework/Versions/3.9/lib/python3.9/multiprocessing/process.py", line 108, in run
    self._target(*self._args, **self._kwargs)
  File "/Users/juanpelos/Documents/.venv/lib/python3.9/site-packages/uvicorn/_subprocess.py", line 73, in subprocess_started
    sys.stdin = os.fdopen(stdin_fileno)  # pragma: full coverage
  File "/Applications/Xcode.app/Contents/Developer/Library/Frameworks/Python3.framework/Versions/3.9/lib/python3.9/os.py", line 1023, in fdopen
    return io.open(fd, *args, **kwargs)
OSError: [Errno 9] Bad file descriptor
WARNING:  WatchFiles detected changes in 'streamlit_app.py'. Reloading...
Process SpawnProcess-37:
Traceback (most recent call last):
  File "/Applications/Xcode.app/Contents/Developer/Library/Frameworks/Python3.framework/Versions/3.9/lib/python3.9/multiprocessing/process.py", line 315, in _bootstrap
    self.run()
  File "/Applications/Xcode.app/Contents/Developer/Library/Frameworks/Python3.framework/Versions/3.9/lib/python3.9/multiprocessing/process.py", line 108, in run
    self._target(*self._args, **self._kwargs)
  File "/Users/juanpelos/Documents/.venv/lib/python3.9/site-packages/uvicorn/_subprocess.py", line 73, in subprocess_started
    sys.stdin = os.fdopen(stdin_fileno)  # pragma: full coverage
  File "/Applications/Xcode.app/Contents/Developer/Library/Frameworks/Python3.framework/Versions/3.9/lib/python3.9/os.py", line 1023, in fdopen
    return io.open(fd, *args, **kwargs)
OSError: [Errno 9] Bad file descriptor
/Users/juanpelos/Documents/Data_Bases/Data_Bases_2.0/project_2/app/streamlit_app.py:44: UserWarning: Could not infer format, so each element will be parsed individually, falling back to `dateutil`. To ensure parsing is consistent and as-expected, please specify a format.
  if df[col].dtype == 'object' and col.endswith("_time"):
/Users/juanpelos/Documents/Data_Bases/Data_Bases_2.0/project_2/app/streamlit_app.py:44: UserWarning: Could not infer format, so each element will be parsed individually, falling back to `dateutil`. To ensure parsing is consistent and as-expected, please specify a format.
  if df[col].dtype == 'object' and col.endswith("_time"):
/Users/juanpelos/Documents/Data_Bases/Data_Bases_2.0/project_2/app/streamlit_app.py:44: UserWarning: Could not infer format, so each element will be parsed individually, falling back to `dateutil`. To ensure parsing is consistent and as-expected, please specify a format.
  if df[col].dtype == 'object' and col.endswith("_time"):
/Users/juanpelos/Documents/Data_Bases/Data_Bases_2.0/project_2/app/streamlit_app.py:44: UserWarning: Could not infer format, so each element will be parsed individually, falling back to `dateutil`. To ensure parsing is consistent and as-expected, please specify a format.
  if df[col].dtype == 'object' and col.endswith("_time"):
/Users/juanpelos/Documents/Data_Bases/Data_Bases_2.0/project_2/app/streamlit_app.py:44: UserWarning: Could not infer format, so each element will be parsed individually, falling back to `dateutil`. To ensure parsing is consistent and as-expected, please specify a format.
  if df[col].dtype == 'object' and col.endswith("_time"):
/Users/juanpelos/Documents/Data_Bases/Data_Bases_2.0/project_2/app/streamlit_app.py:44: UserWarning: Could not infer format, so each element will be parsed individually, falling back to `dateutil`. To ensure parsing is consistent and as-expected, please specify a format.
  if df[col].dtype == 'object' and col.endswith("_time"):
/Users/juanpelos/Documents/Data_Bases/Data_Bases_2.0/project_2/app/streamlit_app.py:44: UserWarning: Could not infer format, so each element will be parsed individually, falling back to `dateutil`. To ensure parsing is consistent and as-expected, please specify a format.
  if df[col].dtype == 'object' and col.endswith("_time"):
/Users/juanpelos/Documents/Data_Bases/Data_Bases_2.0/project_2/app/streamlit_app.py:44: UserWarning: Could not infer format, so each element will be parsed individually, falling back to `dateutil`. To ensure parsing is consistent and as-expected, please specify a format.
  if df[col].dtype == 'object' and col.endswith("_time"):
/Users/juanpelos/Documents/Data_Bases/Data_Bases_2.0/project_2/app/streamlit_app.py:44: UserWarning: Could not infer format, so each element will be parsed individually, falling back to `dateutil`. To ensure parsing is consistent and as-expected, please specify a format.
  if df[col].dtype == 'object' and col.endswith("_time"):
/Users/juanpelos/Documents/Data_Bases/Data_Bases_2.0/project_2/app/streamlit_app.py:44: UserWarning: Could not infer format, so each element will be parsed individually, falling back to `dateutil`. To ensure parsing is consistent and as-expected, please specify a format.
  if df[col].dtype == 'object' and col.endswith("_time"):
WARNING:  WatchFiles detected changes in 'main.py'. Reloading...
Process SpawnProcess-38:
Traceback (most recent call last):
  File "/Applications/Xcode.app/Contents/Developer/Library/Frameworks/Python3.framework/Versions/3.9/lib/python3.9/multiprocessing/process.py", line 315, in _bootstrap
    self.run()
  File "/Applications/Xcode.app/Contents/Developer/Library/Frameworks/Python3.framework/Versions/3.9/lib/python3.9/multiprocessing/process.py", line 108, in run
    self._target(*self._args, **self._kwargs)
  File "/Users/juanpelos/Documents/.venv/lib/python3.9/site-packages/uvicorn/_subprocess.py", line 73, in subprocess_started
    sys.stdin = os.fdopen(stdin_fileno)  # pragma: full coverage
  File "/Applications/Xcode.app/Contents/Developer/Library/Frameworks/Python3.framework/Versions/3.9/lib/python3.9/os.py", line 1023, in fdopen
    return io.open(fd, *args, **kwargs)
OSError: [Errno 9] Bad file descriptor
